Workbook

Sheet Data Set 1
A2: Instructions | I2: Helpful Formulas
A3: 1 | B3: On Data Set 1, fill in data from the missing headers | I3: XLOOKUP | J3: COUNTIF | K3: RIGHT | L3: LEN
A4: 1a | B4: As best as possible. Show all transformation steps in formulas | I4: VLOOKUP | J4: SUM | K4: LEFT | L4: TEXT
A5: 1b | B5: Feel free to add any helper columns | I5: INDEX-MATCH | J5: SUMIF | K5: MID | L5: EDATE | M5: =M6 -> 0
A6: 1c | B6: You can search on the internet or ask the interviewer for help if you get stuck | I6: CONCAT | J6: MAX | K6: TRIM | L6: TODAY
A7: 2 | B7: full_name is first_name and last_name if they exist (i.e "Richard Lee") and blank if not ("") | I7: CONCATENATE | J7: MAXIF | K7: SUBSTITUTE | L7: SEARCH
A8: 3 | B8: displayname is full_name if it exists or company_name. displayname must be unique | I8: IF | J8: AVERAGE | K8: ROUND | L8: FIND
A9: 4 | B9: phone1 and phone2 should be numeric characters only and not start with a 1 | I9: IFNA
A10: 5 | B10: Please mark all customers with no service in 4 years as "Inactive", rest should be "Active"
A13: custId | B13: first_name | C13: last_name | D13: company_name | E13: address | F13: city | G13: state | H13: zip | I13: full_name | J13: displayname | K13: street_num | L13: phone1 | M13: phone2 | N13: email | O13: number_of_vehicles | P13: vehicle1_name | Q13: Vehcile-1 Comp Name | R13: vehicle1_last_service_date | S13: vehicle2_name | T13: Vehcile-2 Comp Name | U13: vehicle2_last_service_date | V13: total mileage | W13: customerlastservice | X13: status | Y13: MileageBrackets
A14: 1475 | D14: Acme Supply Co | E14: 1953 Telegraph Rd | F14: Saint Joseph | G14: MO | H14: 64504 | I14: =_xlfn.CONCAT(B14," ",C14) | J14: =IF(I14=" ",D14,I14) -> Acme Supply Co | K14: =_xlfn.TEXTBEFORE(E14, " ") -> 1953 | L14: =VLOOKUP(A14,'Data Set 3 - Contacts'!$A$2:$F$136,5,FALSE) -> 8165579673 | M14: =VLOOKUP(A14,'Data Set 3 - Contacts'!$A$2:$F$136,6,FALSE) | N14: =VLOOKUP(A14,'Data Set 3 - Contacts'!$A$2:$F$136,4,FALSE) -> diane@cox.net | O14: =_xlfn.XLOOKUP(A14,'Data Set 2 - Vehicles'!$A$2:$A$158,'Data Set 2 - Vehicles'!$B$2:$B$158,0,0,-1) -> 0 | P14: =_xlfn.XLOOKUP(A14,'Data Set 2 - Vehicles'!$A$2:$A$158,'Data Set 2 - Vehicles'!$E$2:$E$158,"Not Found",0,1) -> Not Found | Q14: =IF(_xlfn.CONCAT(_xlfn.XLOOKUP(A14,'Data Set 2 - Vehicles'!$A$2:$A$158,'Data Set 2 - Vehicles'!$D$2:$D$158,"Not Found",0,1)," ",_xlfn.XLOOKUP(A14,'Data Set 2 - Vehicles'!$A$2:$A$158,'Data Set 2 - Vehicles'!$E$2:$E$158,"Not Found",0,1))="Not Found Not Found", "Not Found",_xlfn.CONCAT(_xlfn.XLOOKUP(A14,'Data Set 2 - Vehicles'!$A$2:$A$158,'Data Set 2 - Vehicles'!$D$2:$D$158,"Not Found",0,1)," ",_xlfn.XLOOKUP(A14,'Data Set 2 - Vehicles'!$A$2:$A$158,'Data Set 2 - Vehicles'!$E$2:$E$158,"Not Found",0,1))) -> Not Found | R14: =_xlfn.XLOOKUP(A14,'Data Set 2 - Vehicles'!$A$2:$A$158,'Data Set 2 - Vehicles'!$O$2:$O$158,"",0,1) | S14: =IF(_xlfn.XLOOKUP(A14,'Data Set 2 - Vehicles'!$A$2:$A$158,'Data Set 2 - Vehicles'!$E$2:$E$158,"Has No Vehicle",0,-1)=P14,"Has Only One Vehicle",_xlfn.XLOOKUP(A14,'Data Set 2 - Vehicles'!$A$2:$A$158,'Data Set 2 - Vehicles'!$E$2:$E$158,"Has No Vehicle",0,-1)) -> Has No Vehicle | T14: =_xlfn.LET(_xlpm.mfcname,_xlfn.XLOOKUP(A14,'Data Set 2 - Vehicles'!$A$2:$A$158,'Data Set 2 - Vehicles'!$D$2:$D$158,"NF",0,-1),_xlpm.mdlname,_xlfn.XLOOKUP(A14,'Data Set 2 - Vehicles'!$A$2:$A$158,'Data Set 2 - Vehicles'!$E$2:$E$158,"NF",0,-1),_xlpm.vehcilename,_xlfn.CONCAT(_xlpm.mfcname," ",_xlpm.mdlname),IF(S14="Has No Vehicle","Has No Vehicle",IF(S14="Has Only One Vehicle","Has Only One Vehicle",IF(_xlpm.vehcilename="NF NF","Not Found",_xlpm.vehcilename)))) -> Has No Vehicle | U14: =_xlfn.LET(_xlpm.vserdate,_xlfn.XLOOKUP(A14,'Data Set 2 - Vehicles'!$A$2:$A$158,'Data Set 2 - Vehicles'!$O$2:$O$158,"NF",0,-1), IF(OR('Data Set 1'!S14="Has No Vehicle",'Data Set 1'!S14="Has Only One Vehicle"),'Data Set 1'!S14,_xlpm.vserdate)) -> Has No Vehicle | V14: =SUMIF('Data Set 2 - Vehicles'!$A$2:$A$158,'Data Set 1'!A14,'Data Set 2 - Vehicles'!$Q$2:$Q$158) -> 0 | W14: =_xlfn.LET(_xlpm.maxdate,_xlfn.MAXIFS('Data Set 2 - Vehicles'!$O$2:$O$158,'Data Set 2 - Vehicles'!$A$2:$A$158,'Data Set 1'!A14),IF(_xlpm.maxdate=0,"",_xlpm.maxdate)) | X14: =IF(W14="","No Service Record", IF(W14<EDATE(TODAY(),-48),"InActive","Active")) -> No Service Record | Y14: =IF(tblCustomers[[#This Row],[total mileage]]=0,"Customer has No Car", IF(AND(tblCustomers[[#This Row],[total mileage]]>0,tblCustomers[[#This Row],[total mileage]]<=100000),"50K - 100K", IF(AND(tblCustomers[[#This Row],[total mileage]]>100000,tblCustomers[[#This Row],[total mileage]]<=200000),"100K-200K","Mileage>200k"))) -> Customer has No Car
A15: 1352 | D15: Advantage Martgage Company | E15: 73 W Barstow Ave | F15: Arlington Heights | G15: IL | H15: 60004 | I15: =_xlfn.CONCAT(B15," ",C15) | J15: =IF(I15=" ",D15,I15) -> Advantage Martgage Company | K15: =_xlfn.TEXTBEFORE(E15, " ") -> 73 | L15: =VLOOKUP(A15,'Data Set 3 - Contacts'!$A$2:$F$136,5,FALSE) -> 8473532156 | M15: =VLOOKUP(A15,'Data Set 3 - Contacts'!$A$2:$F$136,6,FALSE) | N15: =VLOOKUP(A15,'Data Set 3 - Contacts'!$A$2:$F$136,4,FALSE) -> wacuff@gmail.com | O15: =_xlfn.XLOOKUP(A15,'Data Set 2 - Vehicles'!$A$2:$A$158,'Data Set 2 - Vehicles'!$B$2:$B$158,0,0,-1) -> 1 | P15: =_xlfn.XLOOKUP(A15,'Data Set 2 - Vehicles'!$A$2:$A$158,'Data Set 2 - Vehicles'!$E$2:$E$158,"Not Found",0,1) -> Mountaineer | Q15: =IF(_xlfn.CONCAT(_xlfn.XLOOKUP(A15,'Data Set 2 - Vehicles'!$A$2:$A$158,'Data Set 2 - Vehicles'!$D$2:$D$158,"Not Found",0,1)," ",_xlfn.XLOOKUP(A15,'Data Set 2 - Vehicles'!$A$2:$A$158,'Data Set 2 - Vehicles'!$E$2:$E$158,"Not Found",0,1))="Not Found Not Found", "Not Found",_xlfn.CONCAT(_xlfn.XLOOKUP(A15,'Data Set 2 - Vehicles'!$A$2:$A$158,'Data Set 2 - Vehicles'!$D$2:$D$158,"Not Found",0,1)," ",_xlfn.XLOOKUP(A15,'Data Set 2 - Vehicles'!$A$2:$A$158,'Data Set 2 - Vehicles'!$E$2:$E$158,"Not Found",0,1))) -> Mercury Mountaineer | R15: =_xlfn.XLOOKUP(A15,'Data Set 2 - Vehicles'!$A$2:$A$158,'Data Set 2 - Vehicles'!$O$2:$O$158,"",0,1) -> 42413 | S15: =IF(_xlfn.XLOOKUP(A15,'Data Set 2 - Vehicles'!$A$2:$A$158,'Data Set 2 - Vehicles'!$E$2:$E$158,"Has No Vehicle",0,-1)=P15,"Has Only One Vehicle",_xlfn.XLOOKUP(A15,'Data Set 2 - Vehicles'!$A$2:$A$158,'Data Set 2 - Vehicles'!$E$2:$E$158,"Has No Vehcile",0,-1)) -> Has Only One Vehicle | T15: =_xlfn.LET(_xlpm.mfcname,_xlfn.XLOOKUP(A15,'Data Set 2 - Vehicles'!$A$2:$A$158,'Data Set 2 - Vehicles'!$D$2:$D$158,"NF",0,-1),_xlpm.mdlname,_xlfn.XLOOKUP(A15,'Data Set 2 - Vehicles'!$A$2:$A$158,'Data Set 2 - Vehicles'!$E$2:$E$158,"NF",0,-1),_xlpm.vehcilename,_xlfn.CONCAT(_xlpm.mfcname," ",_xlpm.mdlname),IF(S15="Has No Vehicle","Has No Vehicle",IF(S15="Has Only One Vehicle","Has Only One Vehicle",IF(_xlpm.vehcilename="NF NF","Not Found",_xlpm.vehcilename)))) -> Has Only One Vehicle | U15: =_xlfn.LET(_xlpm.vserdate,_xlfn.XLOOKUP(A15,'Data Set 2 - Vehicles'!$A$2:$A$158,'Data Set 2 - Vehicles'!$O$2:$O$158,"NF",0,-1), IF(OR('Data Set 1'!S15="Has No Vehicle",'Data Set 1'!S15="Has Only One Vehicle"),'Data Set 1'!S15,_xlpm.vserdate)) -> Has Only One Vehicle | V15: =SUMIF('Data Set 2 - Vehicles'!$A$2:$A$158,'Data Set 1'!A15,'Data Set 2 - Vehicles'!$Q$2:$Q$158) -> 137028 | W15: =_xlfn.LET(_xlpm.maxdate,_xlfn.MAXIFS('Data Set 2 - Vehicles'!$O$2:$O$158,'Data Set 2 - Vehicles'!$A$2:$A$158,'Data Set 1'!A15),IF(_xlpm.maxdate=0,"",_xlpm.maxdate)) -> 42413 | X15: =IF(W15="","No Service Record", IF(W15<EDATE(TODAY(),-48),"InActive","Active")) -> InActive | Y15: =IF(tblCustomers[[#This Row],[total mileage]]=0,"Customer has No Car", IF(AND(tblCustomers[[#This Row],[total mileage]]>0,tblCustomers[[#This Row],[total mileage]]<=100000),"50K - 100K", IF(AND(tblCustomers[[#This Row],[total mileage]]>100000,tblCustomers[[#This Row],[total mileage]]<=200000),"100K-200K","Mileage>200k"))) -> 100K-200K
A16: 1076 | B16: Moon | C16: Parlato | E16: 74989 Brandon St | F16: Wellsville | G16: NY | H16: 14895 | I16: =_xlfn.CONCAT(B16," ",C16) -> Moon Parlato | J16: =IF(I16=" ",D16,I16) -> Moon Parlato | K16: =_xlfn.TEXTBEFORE(E16, " ") -> 74989 | L16: =VLOOKUP(A16,'Data Set 3 - Contacts'!$A$2:$F$136,5,FALSE) -> 5858668313 | M16: =VLOOKUP(A16,'Data Set 3 - Contacts'!$A$2:$F$136,6,FALSE) -> 5854984278 | N16: =VLOOKUP(A16,'Data Set 3 - Contacts'!$A$2:$F$136,4,FALSE) -> moon@yahoo.com | O16: =_xlfn.XLOOKUP(A16,'Data Set 2 - Vehicles'!$A$2:$A$158,'Data Set 2 - Vehicles'!$B$2:$B$158,0,0,-1) -> 2 | P16: =_xlfn.XLOOKUP(A16,'Data Set 2 - Vehicles'!$A$2:$A$158,'Data Set 2 - Vehicles'!$E$2:$E$158,"Not Found",0,1) -> F-Series | Q16: =IF(_xlfn.CONCAT(_xlfn.XLOOKUP(A16,'Data Set 2 - Vehicles'!$A$2:$A$158,'Data Set 2 - Vehicles'!$D$2:$D$158,"Not Found",0,1)," ",_xlfn.XLOOKUP(A16,'Data Set 2 - Vehicles'!$A$2:$A$158,'Data Set 2 - Vehicles'!$E$2:$E$158,"Not Found",0,1))="Not Found Not Found", "Not Found",_xlfn.CONCAT(_xlfn.XLOOKUP(A16,'Data Set 2 - Vehicles'!$A$2:$A$158,'Data Set 2 - Vehicles'!$D$2:$D$158,"Not Found",0,1)," ",_xlfn.XLOOKUP(A16,'Data Set 2 - Vehicles'!$A$2:$A$158,'Data Set 2 - Vehicles'!$E$2:$E$158,"Not Found",0,1))) -> Ford F-Series | R16: =_xlfn.XLOOKUP(A16,'Data Set 2 - Vehicles'!$A$2:$A$158,'Data Set 2 - Vehicles'!$O$2:$O$158,"",0,1) -> 38580 | S16: =IF(_xlfn.XLOOKUP(A16,'Data Set 2 - Vehicles'!$A$2:$A$158,'Data Set 2 - Vehicles'!$E$2:$E$158,"Has No Vehicle",0,-1)=P16,"Has Only One Vehicle",_xlfn.XLOOKUP(A16,'Data Set 2 - Vehicles'!$A$2:$A$158,'Data Set 2 - Vehicles'!$E$2:$E$158,"Has No Vehcile",0,-1)) -> Park Avenue | T16: =_xlfn.LET(_xlpm.mfcname,_xlfn.XLOOKUP(A16,'Data Set 2 - Vehicles'!$A$2:$A$158,'Data Set 2 - Vehicles'!$D$2:$D$158,"NF",0,-1),_xlpm.mdlname,_xlfn.XLOOKUP(A16,'Data Set 2 - Vehicles'!$A$2:$A$158,'Data Set 2 - Vehicles'!$E$2:$E$158,"NF",0,-1),_xlpm.vehcilename,_xlfn.CONCAT(_xlpm.mfcname," ",_xlpm.mdlname),IF(S16="Has No Vehicle","Has No Vehicle",IF(S16="Has Only One Vehicle","Has Only One Vehicle",IF(_xlpm.vehcilename="NF NF","Not Found",_xlpm.vehcilename)))) -> Buick Park Avenue | U16: =_xlfn.LET(_xlpm.vserdate,_xlfn.XLOOKUP(A16,'Data Set 2 - Vehicles'!$A$2:$A$158,'Data Set 2 - Vehicles'!$O$2:$O$158,"NF",0,-1), IF(OR('Data Set 1'!S16="Has No Vehicle",'Data Set 1'!S16="Has Only One Vehicle"),'Data Set 1'!S16,_xlpm.vserdate)) -> 40625 | V16: =SUMIF('Data Set 2 - Vehicles'!$A$2:$A$158,'Data Set 1'!A16,'Data Set 2 - Vehicles'!$Q$2:$Q$158) -> 518924 | W16: =_xlfn.LET(_xlpm.maxdate,_xlfn.MAXIFS('Data Set 2 - Vehicles'!$O$2:$O$158,'Data Set 2 - Vehicles'!$A$2:$A$158,'Data Set 1'!A16),IF(_xlpm.maxdate=0,"",_xlpm.maxdate)) -> 40625 | X16: =IF(W16="","No Service Record", IF(W16<EDATE(TODAY(),-48),"InActive","Active")) -> InActive | Y16: =IF(tblCustomers[[#This Row],[total mileage]]=0,"Customer has No Car", IF(AND(tblCustomers[[#This Row],[total mileage]]>0,tblCustomers[[#This Row],[total mileage]]<=100000),"50K - 100K", IF(AND(tblCustomers[[#This Row],[total mileage]]>100000,tblCustomers[[#This Row],[total mileage]]<=200000),"100K-200K","Mileage>200k"))) -> Mileage>200k
A17: 1180 | D17: Anchorage Museum Of Hist & Art | E17: 3 State Route 35 S | F17: Paramus | G17: NJ | H17: 7652 | I17: =_xlfn.CONCAT(B17," ",C17) | J17: =IF(I17=" ",D17,I17) -> Anchorage Museum Of Hist & Art | K17: =_xlfn.TEXTBEFORE(E17, " ") -> 3 | L17: =VLOOKUP(A17,'Data Set 3 - Contacts'!$A$2:$F$136,5,FALSE) -> 2019711638 | M17: =VLOOKUP(A17,'Data Set 3 - Contacts'!$A$2:$F$136,6,FALSE) -> 2012478925 | N17: =VLOOKUP(A17,'Data Set 3 - Contacts'!$A$2:$F$136,4,FALSE) -> nelida@gmail.com | O17: =_xlfn.XLOOKUP(A17,'Data Set 2 - Vehicles'!$A$2:$A$158,'Data Set 2 - Vehicles'!$B$2:$B$158,0,0,-1) -> 1 | P17: =_xlfn.XLOOKUP(A17,'Data Set 2 - Vehicles'!$A$2:$A$158,'Data Set 2 - Vehicles'!$E$2:$E$158,"Not Found",0,1) -> Intrepid | Q17: =IF(_xlfn.CONCAT(_xlfn.XLOOKUP(A17,'Data Set 2 - Vehicles'!$A$2:$A$158,'Data Set 2 - Vehicles'!$D$2:$D$158,"Not Found",0,1)," ",_xlfn.XLOOKUP(A17,'Data Set 2 - Vehicles'!$A$2:$A$158,'Data Set 2 - Vehicles'!$E$2:$E$158,"Not Found",0,1))="Not Found Not Found", "Not Found",_xlfn.CONCAT(_xlfn.XLOOKUP(A17,'Data Set 2 - Vehicles'!$A$2:$A$158,'Data Set 2 - Vehicles'!$D$2:$D$158,"Not Found",0,1)," ",_xlfn.XLOOKUP(A17,'Data Set 2 - Vehicles'!$A$2:$A$158,'Data Set 2 - Vehicles'!$E$2:$E$158,"Not Found",0,1))) -> Dodge Intrepid | R17: =_xlfn.XLOOKUP(A17,'Data Set 2 - Vehicles'!$A$2:$A$158,'Data Set 2 - Vehicles'!$O$2:$O$158,"",0,1) -> 45079 | S17: =IF(_xlfn.XLOOKUP(A17,'Data Set 2 - Vehicles'!$A$2:$A$158,'Data Set 2 - Vehicles'!$E$2:$E$158,"Has No Vehicle",0,-1)=P17,"Has Only One Vehicle",_xlfn.XLOOKUP(A17,'Data Set 2 - Vehicles'!$A$2:$A$158,'Data Set 2 - Vehicles'!$E$2:$E$158,"Has No Vehcile",0,-1)) -> Has Only One Vehicle | T17: =_xlfn.LET(_xlpm.mfcname,_xlfn.XLOOKUP(A17,'Data Set 2 - Vehicles'!$A$2:$A$158,'Data Set 2 - Vehicles'!$D$2:$D$158,"NF",0,-1),_xlpm.mdlname,_xlfn.XLOOKUP(A17,'Data Set 2 - Vehicles'!$A$2:$A$158,'Data Set 2 - Vehicles'!$E$2:$E$158,"NF",0,-1),_xlpm.vehcilename,_xlfn.CONCAT(_xlpm.mfcname," ",_xlpm.mdlname),IF(S17="Has No Vehicle","Has No Vehicle",IF(S17="Has Only One Vehicle","Has Only One Vehicle",IF(_xlpm.vehcilename="NF NF","Not Found",_xlpm.vehcilename)))) -> Has Only One Vehicle | U17: =_xlfn.LET(_xlpm.vserdate,_xlfn.XLOOKUP(A17,'Data Set 2 - Vehicles'!$A$2:$A$158,'Data Set 2 - Vehicles'!$O$2:$O$158,"NF",0,-1), IF(OR('Data Set 1'!S17="Has No Vehicle",'Data Set 1'!S17="Has Only One Vehicle"),'Data Set 1'!S17,_xlpm.vserdate)) -> Has Only One Vehicle | V17: =SUMIF('Data Set 2 - Vehicles'!$A$2:$A$158,'Data Set 1'!A17,'Data Set 2 - Vehicles'!$Q$2:$Q$158) -> 247285 | W17: =_xlfn.LET(_xlpm.maxdate,_xlfn.MAXIFS('Data Set 2 - Vehicles'!$O$2:$O$158,'Data Set 2 - Vehicles'!$A$2:$A$158,'Data Set 1'!A17),IF(_xlpm.maxdate=0,"",_xlpm.maxdate)) -> 45079 | X17: =IF(W17="","No Service Record", IF(W17<EDATE(TODAY(),-48),"InActive","Active")) -> Active | Y17: =IF(tblCustomers[[#This Row],[total mileage]]=0,"Customer has No Car", IF(AND(tblCustomers[[#This Row],[total mileage]]>0,tblCustomers[[#This Row],[total mileage]]<=100000),"50K - 100K", IF(AND(tblCustomers[[#This Row],[total mileage]]>100000,tblCustomers[[#This Row],[total mileage]]<=200000),"100K-200K","Mileage>200k"))) -> Mileage>200k
A18: 1177 | B18: Joesph | C18: Degonia | D18: A R Packaging | E18: 2887 Knowlton St #5435 | F18: Berkeley | G18: CA | H18: 94710 | I18: =_xlfn.CONCAT(B18," ",C18) -> Joesph Degonia | J18: =IF(I18=" ",D18,I18) -> Joesph Degonia | K18: =_xlfn.TEXTBEFORE(E18, " ") -> 2887 | L18: =VLOOKUP(A18,'Data Set 3 - Contacts'!$A$2:$F$136,5,FALSE) -> 5106779785 | M18: =VLOOKUP(A18,'Data Set 3 - Contacts'!$A$2:$F$136,6,FALSE) -> 5109425916 | N18: =VLOOKUP(A18,'Data Set 3 - Contacts'!$A$2:$F$136,4,FALSE) -> joesph_degonia@degonia.org | O18: =_xlfn.XLOOKUP(A18,'Data Set 2 - Vehicles'!$A$2:$A$158,'Data Set 2 - Vehicles'!$B$2:$B$158,0,0,-1) -> 2 | P18: =_xlfn.XLOOKUP(A18,'Data Set 2 - Vehicles'!$A$2:$A$158,'Data Set 2 - Vehicles'!$E$2:$E$158,"Not Found",0,1) -> 328i | Q18: =IF(_xlfn.CONCAT(_xlfn.XLOOKUP(A18,'Data Set 2 - Vehicles'!$A$2:$A$158,'Data Set 2 - Vehicles'!$D$2:$D$158,"Not Found",0,1)," ",_xlfn.XLOOKUP(A18,'Data Set 2 - Vehicles'!$A$2:$A$158,'Data Set 2 - Vehicles'!$E$2:$E$158,"Not Found",0,1))="Not Found Not Found", "Not Found",_xlfn.CONCAT(_xlfn.XLOOKUP(A18,'Data Set 2 - Vehicles'!$A$2:$A$158,'Data Set 2 - Vehicles'!$D$2:$D$158,"Not Found",0,1)," ",_xlfn.XLOOKUP(A18,'Data Set 2 - Vehicles'!$A$2:$A$158,'Data Set 2 - Vehicles'!$E$2:$E$158,"Not Found",0,1))) -> BMW 328i | R18: =_xlfn.XLOOKUP(A18,'Data Set 2 - Vehicles'!$A$2:$A$158,'Data Set 2 - Vehicles'!$O$2:$O$158,"",0,1) -> 39111 | S18: =IF(_xlfn.XLOOKUP(A18,'Data Set 2 - Vehicles'!$A$2:$A$158,'Data Set 2 - Vehicles'!$E$2:$E$158,"Has No Vehicle",0,-1)=P18,"Has Only One Vehicle",_xlfn.XLOOKUP(A18,'Data Set 2 - Vehicles'!$A$2:$A$158,'Data Set 2 - Vehicles'!$E$2:$E$158,"Has No Vehcile",0,-1)) -> Explorer | T18: =_xlfn.LET(_xlpm.mfcname,_xlfn.XLOOKUP(A18,'Data Set 2 - Vehicles'!$A$2:$A$158,'Data Set 2 - Vehicles'!$D$2:$D$158,"NF",0,-1),_xlpm.mdlname,_xlfn.XLOOKUP(A18,'Data Set 2 - Vehicles'!$A$2:$A$158,'Data Set 2 - Vehicles'!$E$2:$E$158,"NF",0,-1),_xlpm.vehcilename,_xlfn.CONCAT(_xlpm.mfcname," ",_xlpm.mdlname),IF(S18="Has No Vehicle","Has No Vehicle",IF(S18="Has Only One Vehicle","Has Only One Vehicle",IF(_xlpm.vehcilename="NF NF","Not Found",_xlpm.vehcilename)))) -> Ford Explorer | U18: =_xlfn.LET(_xlpm.vserdate,_xlfn.XLOOKUP(A18,'Data Set 2 - Vehicles'!$A$2:$A$158,'Data Set 2 - Vehicles'!$O$2:$O$158,"NF",0,-1), IF(OR('Data Set 1'!S18="Has No Vehicle",'Data Set 1'!S18="Has Only One Vehicle"),'Data Set 1'!S18,_xlpm.vserdate)) -> 44676 | V18: =SUMIF('Data Set 2 - Vehicles'!$A$2:$A$158,'Data Set 1'!A18,'Data Set 2 - Vehicles'!$Q$2:$Q$158) -> 356504 | W18: =_xlfn.LET(_xlpm.maxdate,_xlfn.MAXIFS('Data Set 2 - Vehicles'!$O$2:$O$158,'Data Set 2 - Vehicles'!$A$2:$A$158,'Data Set 1'!A18),IF(_xlpm.maxdate=0,"",_xlpm.maxdate)) -> 44676 | X18: =IF(W18="","No Service Record", IF(W18<EDATE(TODAY(),-48),"InActive","Active")) -> InActive | Y18: =IF(tblCustomers[[#This Row],[total mileage]]=0,"Customer has No Car", IF(AND(tblCustomers[[#This Row],[total mileage]]>0,tblCustomers[[#This Row],[total mileage]]<=100000),"50K - 100K", IF(AND(tblCustomers[[#This Row],[total mileage]]>100000,tblCustomers[[#This Row],[total mileage]]<=200000),"100K-200K","Mileage>200k"))) -> Mileage>200k
A19: 1132 | B19: Howard | C19: Paulas | E19: 866 34th Ave | F19: Denver | G19: CO | H19: 80231 | I19: =_xlfn.CONCAT(B19," ",C19) -> Howard Paulas | J19: =IF(I19=" ",D19,I19) -> Howard Paulas | K19: =_xlfn.TEXTBEFORE(E19, " ") -> 866 | L19: =VLOOKUP(A19,'Data Set 3 - Contacts'!$A$2:$F$136,5,FALSE) -> 3036234241 | M19: =VLOOKUP(A19,'Data Set 3 - Contacts'!$A$2:$F$136,6,FALSE) | N19: =VLOOKUP(A19,'Data Set 3 - Contacts'!$A$2:$F$136,4,FALSE) -> hpaulas@gmail.com | O19: =_xlfn.XLOOKUP(A19,'Data Set 2 - Vehicles'!$A$2:$A$158,'Data Set 2 - Vehicles'!$B$2:$B$158,0,0,-1) -> 2 | P19: =_xlfn.XLOOKUP(A19,'Data Set 2 - Vehicles'!$A$2:$A$158,'Data Set 2 - Vehicles'!$E$2:$E$158,"Not Found",0,1) -> Grand Am | Q19: =IF(_xlfn.CONCAT(_xlfn.XLOOKUP(A19,'Data Set 2 - Vehicles'!$A$2:$A$158,'Data Set 2 - Vehicles'!$D$2:$D$158,"Not Found",0,1)," ",_xlfn.XLOOKUP(A19,'Data Set 2 - Vehicles'!$A$2:$A$158,'Data Set 2 - Vehicles'!$E$2:$E$158,"Not Found",0,1))="Not Found Not Found", "Not Found",_xlfn.CONCAT(_xlfn.XLOOKUP(A19,'Data Set 2 - Vehicles'!$A$2:$A$158,'Data Set 2 - Vehicles'!$D$2:$D$158,"Not Found",0,1)," ",_xlfn.XLOOKUP(A19,'Data Set 2 - Vehicles'!$A$2:$A$158,'Data Set 2 - Vehicles'!$E$2:$E$158,"Not Found",0,1))) -> Pontiac Grand Am | R19: =_xlfn.XLOOKUP(A19,'Data Set 2 - Vehicles'!$A$2:$A$158,'Data Set 2 - Vehicles'!$O$2:$O$158,"",0,1) -> 41969 | S19: =IF(_xlfn.XLOOKUP(A19,'Data Set 2 - Vehicles'!$A$2:$A$158,'Data Set 2 - Vehicles'!$E$2:$E$158,"Has No Vehicle",0,-1)=P19,"Has Only One Vehicle",_xlfn.XLOOKUP(A19,'Data Set 2 - Vehicles'!$A$2:$A$158,'Data Set 2 - Vehicles'!$E$2:$E$158,"Has No Vehcile",0,-1)) -> 4Runner | T19: =_xlfn.LET(_xlpm.mfcname,_xlfn.XLOOKUP(A19,'Data Set 2 - Vehicles'!$A$2:$A$158,'Data Set 2 - Vehicles'!$D$2:$D$158,"NF",0,-1),_xlpm.mdlname,_xlfn.XLOOKUP(A19,'Data Set 2 - Vehicles'!$A$2:$A$158,'Data Set 2 - Vehicles'!$E$2:$E$158,"NF",0,-1),_xlpm.vehcilename,_xlfn.CONCAT(_xlpm.mfcname," ",_xlpm.mdlname),IF(S19="Has No Vehicle","Has No Vehicle",IF(S19="Has Only One Vehicle","Has Only One Vehicle",IF(_xlpm.vehcilename="NF NF","Not Found",_xlpm.vehcilename)))) -> Toyota 4Runner | U19: =_xlfn.LET(_xlpm.vserdate,_xlfn.XLOOKUP(A19,'Data Set 2 - Vehicles'!$A$2:$A$158,'Data Set 2 - Vehicles'!$O$2:$O$158,"NF",0,-1), IF(OR('Data Set 1'!S19="Has No Vehicle",'Data Set 1'!S19="Has Only One Vehicle"),'Data Set 1'!S19,_xlpm.vserdate)) -> 42436 | V19: =SUMIF('Data Set 2 - Vehicles'!$A$2:$A$158,'Data Set 1'!A19,'Data Set 2 - Vehicles'!$Q$2:$Q$158) -> 329686 | W19: =_xlfn.LET(_xlpm.maxdate,_xlfn.MAXIFS('Data Set 2 - Vehicles'!$O$2:$O$158,'Data Set 2 - Vehicles'!$A$2:$A$158,'Data Set 1'!A19),IF(_xlpm.maxdate=0,"",_xlpm.maxdate)) -> 42436 | X19: =IF(W19="","No Service Record", IF(W19<EDATE(TODAY(),-48),"InActive","Active")) -> InActive | Y19: =IF(tblCustomers[[#This Row],[total mileage]]=0,"Customer has No Car", IF(AND(tblCustomers[[#This Row],[total mileage]]>0,tblCustomers[[#This Row],[total mileage]]<=100000),"50K - 100K", IF(AND(tblCustomers[[#This Row],[total mileage]]>100000,tblCustomers[[#This Row],[total mileage]]<=200000),"100K-200K","Mileage>200k"))) -> Mileage>200k
A20: 1372 | D20: Baird Kurtz & Dobson | E20: 82 Winsor St #54 | F20: Atlanta | G20: GA | H20: 30340 | I20: =_xlfn.CONCAT(B20," ",C20) | J20: =IF(I20=" ",D20,I20) -> Baird Kurtz & Dobson | K20: =_xlfn.TEXTBEFORE(E20, " ") -> 82 | L20: =VLOOKUP(A20,'Data Set 3 - Contacts'!$A$2:$F$136,5,FALSE) -> 7708443447 | M20: =VLOOKUP(A20,'Data Set 3 - Contacts'!$A$2:$F$136,6,FALSE) -> 7705844119 | N20: =VLOOKUP(A20,'Data Set 3 - Contacts'!$A$2:$F$136,4,FALSE) -> izetta.funnell@hotmail.com | O20: =_xlfn.XLOOKUP(A20,'Data Set 2 - Vehicles'!$A$2:$A$158,'Data Set 2 - Vehicles'!$B$2:$B$158,0,0,-1) -> 2 | P20: =_xlfn.XLOOKUP(A20,'Data Set 2 - Vehicles'!$A$2:$A$158,'Data Set 2 - Vehicles'!$E$2:$E$158,"Not Found",0,1) -> Tacoma | Q20: =IF(_xlfn.CONCAT(_xlfn.XLOOKUP(A20,'Data Set 2 - Vehicles'!$A$2:$A$158,'Data Set 2 - Vehicles'!$D$2:$D$158,"Not Found",0,1)," ",_xlfn.XLOOKUP(A20,'Data Set 2 - Vehicles'!$A$2:$A$158,'Data Set 2 - Vehicles'!$E$2:$E$158,"Not Found",0,1))="Not Found Not Found", "Not Found",_xlfn.CONCAT(_xlfn.XLOOKUP(A20,'Data Set 2 - Vehicles'!$A$2:$A$158,'Data Set 2 - Vehicles'!$D$2:$D$158,"Not Found",0,1)," ",_xlfn.XLOOKUP(A20,'Data Set 2 - Vehicles'!$A$2:$A$158,'Data Set 2 - Vehicles'!$E$2:$E$158,"Not Found",0,1))) -> Toyota Tacoma | R20: =_xlfn.XLOOKUP(A20,'Data Set 2 - Vehicles'!$A$2:$A$158,'Data Set 2 - Vehicles'!$O$2:$O$158,"",0,1) -> 41122 | S20: =IF(_xlfn.XLOOKUP(A20,'Data Set 2 - Vehicles'!$A$2:$A$158,'Data Set 2 - Vehicles'!$E$2:$E$158,"Has No Vehicle",0,-1)=P20,"Has Only One Vehicle",_xlfn.XLOOKUP(A20,'Data Set 2 - Vehicles'!$A$2:$A$158,'Data Set 2 - Vehicles'!$E$2:$E$158,"Has No Vehcile",0,-1)) -> Voyager | T20: =_xlfn.LET(_xlpm.mfcname,_xlfn.XLOOKUP(A20,'Data Set 2 - Vehicles'!$A$2:$A$158,'Data Set 2 - Vehicles'!$D$2:$D$158,"NF",0,-1),_xlpm.mdlname,_xlfn.XLOOKUP(A20,'Data Set 2 - Vehicles'!$A$2:$A$158,'Data Set 2 - Vehicles'!$E$2:$E$158,"NF",0,-1),_xlpm.vehcilename,_xlfn.CONCAT(_xlpm.mfcname," ",_xlpm.mdlname),IF(S20="Has No Vehicle","Has No Vehicle",IF(S20="Has Only One Vehicle","Has Only One Vehicle",IF(_xlpm.vehcilename="NF NF","Not Found",_xlpm.vehcilename)))) -> Plymouth Voyager | U20: =_xlfn.LET(_xlpm.vserdate,_xlfn.XLOOKUP(A20,'Data Set 2 - Vehicles'!$A$2:$A$158,'Data Set 2 - Vehicles'!$O$2:$O$158,"NF",0,-1), IF(OR('Data Set 1'!S20="Has No Vehicle",'Data Set 1'!S20="Has Only One Vehicle"),'Data Set 1'!S20,_xlpm.vserdate)) -> 45040 | V20: =SUMIF('Data Set 2 - Vehicles'!$A$2:$A$158,'Data Set 1'!A20,'Data Set 2 - Vehicles'!$Q$2:$Q$158) -> 331078 | W20: =_xlfn.LET(_xlpm.maxdate,_xlfn.MAXIFS('Data Set 2 - Vehicles'!$O$2:$O$158,'Data Set 2 - Vehicles'!$A$2:$A$158,'Data Set 1'!A20),IF(_xlpm.maxdate=0,"",_xlpm.maxdate)) -> 45040 | X20: =IF(W20="","No Service Record", IF(W20<EDATE(TODAY(),-48),"InActive","Active")) -> Active | Y20: =IF(tblCustomers[[#This Row],[total mileage]]=0,"Customer has No Car", IF(AND(tblCustomers[[#This Row],[total mileage]]>0,tblCustomers[[#This Row],[total mileage]]<=100000),"50K - 100K", IF(AND(tblCustomers[[#This Row],[total mileage]]>100000,tblCustomers[[#This Row],[total mileage]]<=200000),"100K-200K","Mileage>200k"))) -> Mileage>200k
A21: 1052 | B21: Lorrie | C21: Nestle | D21: Ballard Spahr Andrews | E21: 39 S 7th St | F21: Tullahoma | G21: TN | H21: 37388 | I21: =_xlfn.CONCAT(B21," ",C21) -> Lorrie Nestle | J21: =IF(I21=" ",D21,I21) -> Lorrie Nestle | K21: =_xlfn.TEXTBEFORE(E21, " ") -> 39 | L21: =VLOOKUP(A21,'Data Set 3 - Contacts'!$A$2:$F$136,5,FALSE) -> 9318756644 | M21: =VLOOKUP(A21,'Data Set 3 - Contacts'!$A$2:$F$136,6,FALSE) | N21: =VLOOKUP(A21,'Data Set 3 - Contacts'!$A$2:$F$136,4,FALSE) -> lnestle@hotmail.com | O21: =_xlfn.XLOOKUP(A21,'Data Set 2 - Vehicles'!$A$2:$A$158,'Data Set 2 - Vehicles'!$B$2:$B$158,0,0,-1) -> 1 | P21: =_xlfn.XLOOKUP(A21,'Data Set 2 - Vehicles'!$A$2:$A$158,'Data Set 2 - Vehicles'!$E$2:$E$158,"Not Found",0,1) -> LS400 | Q21: =IF(_xlfn.CONCAT(_xlfn.XLOOKUP(A21,'Data Set 2 - Vehicles'!$A$2:$A$158,'Data Set 2 - Vehicles'!$D$2:$D$158,"Not Found",0,1)," ",_xlfn.XLOOKUP(A21,'Data Set 2 - Vehicles'!$A$2:$A$158,'Data Set 2 - Vehicles'!$E$2:$E$158,"Not Found",0,1))="Not Found Not Found", "Not Found",_xlfn.CONCAT(_xlfn.XLOOKUP(A21,'Data Set 2 - Vehicles'!$A$2:$A$158,'Data Set 2 - Vehicles'!$D$2:$D$158,"Not Found",0,1)," ",_xlfn.XLOOKUP(A21,'Data Set 2 - Vehicles'!$A$2:$A$158,'Data Set 2 - Vehicles'!$E$2:$E$158,"Not Found",0,1))) -> Lexus LS400 | R21: =_xlfn.XLOOKUP(A21,'Data Set 2 - Vehicles'!$A$2:$A$158,'Data Set 2 - Vehicles'!$O$2:$O$158,"",0,1) -> 45380 | S21: =IF(_xlfn.XLOOKUP(A21,'Data Set 2 - Vehicles'!$A$2:$A$158,'Data Set 2 - Vehicles'!$E$2:$E$158,"Has No Vehicle",0,-1)=P21,"Has Only One Vehicle",_xlfn.XLOOKUP(A21,'Data Set 2 - Vehicles'!$A$2:$A$158,'Data Set 2 - Vehicles'!$E$2:$E$158,"Has No Vehcile",0,-1)) -> Has Only One Vehicle | T21: =_xlfn.LET(_xlpm.mfcname,_xlfn.XLOOKUP(A21,'Data Set 2 - Vehicles'!$A$2:$A$158,'Data Set 2 - Vehicles'!$D$2:$D$158,"NF",0,-1),_xlpm.mdlname,_xlfn.XLOOKUP(A21,'Data Set 2 - Vehicles'!$A$2:$A$158,'Data Set 2 - Vehicles'!$E$2:$E$158,"NF",0,-1),_xlpm.vehcilename,_xlfn.CONCAT(_xlpm.mfcname," ",_xlpm.mdlname),IF(S21="Has No Vehicle","Has No Vehicle",IF(S21="Has Only One Vehicle","Has Only One Vehicle",IF(_xlpm.vehcilename="NF NF","Not Found",_xlpm.vehcilename)))) -> Has Only One Vehicle | U21: =_xlfn.LET(_xlpm.vserdate,_xlfn.XLOOKUP(A21,'Data Set 2 - Vehicles'!$A$2:$A$158,'Data Set 2 - Vehicles'!$O$2:$O$158,"NF",0,-1), IF(OR('Data Set 1'!S21="Has No Vehicle",'Data Set 1'!S21="Has Only One Vehicle"),'Data Set 1'!S21,_xlpm.vserdate)) -> Has Only One Vehicle | V21: =SUMIF('Data Set 2 - Vehicles'!$A$2:$A$158,'Data Set 1'!A21,'Data Set 2 - Vehicles'!$Q$2:$Q$158) -> 92262 | W21: =_xlfn.LET(_xlpm.maxdate,_xlfn.MAXIFS('Data Set 2 - Vehicles'!$O$2:$O$158,'Data Set 2 - Vehicles'!$A$2:$A$158,'Data Set 1'!A21),IF(_xlpm.maxdate=0,"",_xlpm.maxdate)) -> 45380 | X21: =IF(W21="","No Service Record", IF(W21<EDATE(TODAY(),-48),"InActive","Active")) -> Active | Y21: =IF(tblCustomers[[#This Row],[total mileage]]=0,"Customer has No Car", IF(AND(tblCustomers[[#This Row],[total mileage]]>0,tblCustomers[[#This Row],[total mileage]]<=100000),"50K - 100K", IF(AND(tblCustomers[[#This Row],[total mileage]]>100000,tblCustomers[[#This Row],[total mileage]]<=200000),"100K-200K","Mileage>200k"))) -> 50K - 100K
A22: 1174 | B22: Sylvia | C22: Cousey | E22: 287 Youngstown Warren Rd | F22: Hampstead | G22: MD | H22: 21074 | I22: =_xlfn.CONCAT(B22," ",C22) -> Sylvia Cousey | J22: =IF(I22=" ",D22,I22) -> Sylvia Cousey | K22: =_xlfn.TEXTBEFORE(E22, " ") -> 287 | L22: =VLOOKUP(A22,'Data Set 3 - Contacts'!$A$2:$F$136,5,FALSE) -> 4102099545 | M22: =VLOOKUP(A22,'Data Set 3 - Contacts'!$A$2:$F$136,6,FALSE) | N22: =VLOOKUP(A22,'Data Set 3 - Contacts'!$A$2:$F$136,4,FALSE) -> sylvia_cousey@cousey.org | O22: =_xlfn.XLOOKUP(A22,'Data Set 2 - Vehicles'!$A$2:$A$158,'Data Set 2 - Vehicles'!$B$2:$B$158,0,0,-1) -> 1 | P22: =_xlfn.XLOOKUP(A22,'Data Set 2 - Vehicles'!$A$2:$A$158,'Data Set 2 - Vehicles'!$E$2:$E$158,"Not Found",0,1) -> Sonata | Q22: =IF(_xlfn.CONCAT(_xlfn.XLOOKUP(A22,'Data Set 2 - Vehicles'!$A$2:$A$158,'Data Set 2 - Vehicles'!$D$2:$D$158,"Not Found",0,1)," ",_xlfn.XLOOKUP(A22,'Data Set 2 - Vehicles'!$A$2:$A$158,'Data Set 2 - Vehicles'!$E$2:$E$158,"Not Found",0,1))="Not Found Not Found", "Not Found",_xlfn.CONCAT(_xlfn.XLOOKUP(A22,'Data Set 2 - Vehicles'!$A$2:$A$158,'Data Set 2 - Vehicles'!$D$2:$D$158,"Not Found",0,1)," ",_xlfn.XLOOKUP(A22,'Data Set 2 - Vehicles'!$A$2:$A$158,'Data Set 2 - Vehicles'!$E$2:$E$158,"Not Found",0,1))) -> Hyundai Sonata | R22: =_xlfn.XLOOKUP(A22,'Data Set 2 - Vehicles'!$A$2:$A$158,'Data Set 2 - Vehicles'!$O$2:$O$158,"",0,1) -> 44726 | S22: =IF(_xlfn.XLOOKUP(A22,'Data Set 2 - Vehicles'!$A$2:$A$158,'Data Set 2 - Vehicles'!$E$2:$E$158,"Has No Vehicle",0,-1)=P22,"Has Only One Vehicle",_xlfn.XLOOKUP(A22,'Data Set 2 - Vehicles'!$A$2:$A$158,'Data Set 2 - Vehicles'!$E$2:$E$158,"Has No Vehcile",0,-1)) -> Has Only One Vehicle | T22: =_xlfn.LET(_xlpm.mfcname,_xlfn.XLOOKUP(A22,'Data Set 2 - Vehicles'!$A$2:$A$158,'Data Set 2 - Vehicles'!$D$2:$D$158,"NF",0,-1),_xlpm.mdlname,_xlfn.XLOOKUP(A22,'Data Set 2 - Vehicles'!$A$2:$A$158,'Data Set 2 - Vehicles'!$E$2:$E$158,"NF",0,-1),_xlpm.vehcilename,_xlfn.CONCAT(_xlpm.mfcname," ",_xlpm.mdlname),IF(S22="Has No Vehicle","Has No Vehicle",IF(S22="Has Only One Vehicle","Has Only One Vehicle",IF(_xlpm.vehcilename="NF NF","Not Found",_xlpm.vehcilename)))) -> Has Only One Vehicle | U22: =_xlfn.LET(_xlpm.vserdate,_xlfn.XLOOKUP(A22,'Data Set 2 - Vehicles'!$A$2:$A$158,'Data Set 2 - Vehicles'!$O$2:$O$158,"NF",0,-1), IF(OR('Data Set 1'!S22="Has No Vehicle",'Data Set 1'!S22="Has Only One Vehicle"),'Data Set 1'!S22,_xlpm.vserdate)) -> Has Only One Vehicle | V22: =SUMIF('Data Set 2 - Vehicles'!$A$2:$A$158,'Data Set 1'!A22,'Data Set 2 - Vehicles'!$Q$2:$Q$158) -> 161021 | W22: =_xlfn.LET(_xlpm.maxdate,_xlfn.MAXIFS('Data Set 2 - Vehicles'!$O$2:$O$158,'Data Set 2 - Vehicles'!$A$2:$A$158,'Data Set 1'!A22),IF(_xlpm.maxdate=0,"",_xlpm.maxdate)) -> 44726 | X22: =IF(W22="","No Service Record", IF(W22<EDATE(TODAY(),-48),"InActive","Active")) -> InActive | Y22: =IF(tblCustomers[[#This Row],[total mileage]]=0,"Customer has No Car", IF(AND(tblCustomers[[#This Row],[total mileage]]>0,tblCustomers[[#This Row],[total mileage]]<=100000),"50K - 100K", IF(AND(tblCustomers[[#This Row],[total mileage]]>100000,tblCustomers[[#This Row],[total mileage]]<=200000),"100K-200K","Mileage>200k"))) -> 100K-200K
A23: 1340 | B23: Sherita | C23: Saras | D23: Black History Resource Center | E23: 8 Us Highway 22 | F23: Colorado Springs | G23: CO | H23: 80937 | I23: =_xlfn.CONCAT(B23," ",C23) -> Sherita Saras | J23: =IF(I23=" ",D23,I23) -> Sherita Saras | K23: =_xlfn.TEXTBEFORE(E23, " ") -> 8 | L23: =VLOOKUP(A23,'Data Set 3 - Contacts'!$A$2:$F$136,5,FALSE) -> 7196691664 | M23: =VLOOKUP(A23,'Data Set 3 - Contacts'!$A$2:$F$136,6,FALSE) -> 7195479543 | N23: =VLOOKUP(A23,'Data Set 3 - Contacts'!$A$2:$F$136,4,FALSE) -> sherita.saras@cox.net | O23: =_xlfn.XLOOKUP(A23,'Data Set 2 - Vehicles'!$A$2:$A$158,'Data Set 2 - Vehicles'!$B$2:$B$158,0,0,-1) -> 1 | P23: =_xlfn.XLOOKUP(A23,'Data Set 2 - Vehicles'!$A$2:$A$158,'Data Set 2 - Vehicles'!$E$2:$E$158,"Not Found",0,1) -> Outback | Q23: =IF(_xlfn.CONCAT(_xlfn.XLOOKUP(A23,'Data Set 2 - Vehicles'!$A$2:$A$158,'Data Set 2 - Vehicles'!$D$2:$D$158,"Not Found",0,1)," ",_xlfn.XLOOKUP(A23,'Data Set 2 - Vehicles'!$A$2:$A$158,'Data Set 2 - Vehicles'!$E$2:$E$158,"Not Found",0,1))="Not Found Not Found", "Not Found",_xlfn.CONCAT(_xlfn.XLOOKUP(A23,'Data Set 2 - Vehicles'!$A$2:$A$158,'Data Set 2 - Vehicles'!$D$2:$D$158,"Not Found",0,1)," ",_xlfn.XLOOKUP(A23,'Data Set 2 - Vehicles'!$A$2:$A$158,'Data Set 2 - Vehicles'!$E$2:$E$158,"Not Found",0,1))) -> Subaru Outback | R23: =_xlfn.XLOOKUP(A23,'Data Set 2 - Vehicles'!$A$2:$A$158,'Data Set 2 - Vehicles'!$O$2:$O$158,"",0,1) -> 39636 | S23: =IF(_xlfn.XLOOKUP(A23,'Data Set 2 - Vehicles'!$A$2:$A$158,'Data Set 2 - Vehicles'!$E$2:$E$158,"Has No Vehicle",0,-1)=P23,"Has Only One Vehicle",_xlfn.XLOOKUP(A23,'Data Set 2 - Vehicles'!$A$2:$A$158,'Data Set 2 - Vehicles'!$E$2:$E$158,"Has No Vehcile",0,-1)) -> Has Only One Vehicle | T23: =_xlfn.LET(_xlpm.mfcname,_xlfn.XLOOKUP(A23,'Data Set 2 - Vehicles'!$A$2:$A$158,'Data Set 2 - Vehicles'!$D$2:$D$158,"NF",0,-1),_xlpm.mdlname,_xlfn.XLOOKUP(A23,'Data Set 2 - Vehicles'!$A$2:$A$158,'Data Set 2 - Vehicles'!$E$2:$E$158,"NF",0,-1),_xlpm.vehcilename,_xlfn.CONCAT(_xlpm.mfcname," ",_xlpm.mdlname),IF(S23="Has No Vehicle","Has No Vehicle",IF(S23="Has Only One Vehicle","Has Only One Vehicle",IF(_xlpm.vehcilename="NF NF","Not Found",_xlpm.vehcilename)))) -> Has Only One Vehicle | U23: =_xlfn.LET(_xlpm.vserdate,_xlfn.XLOOKUP(A23,'Data Set 2 - Vehicles'!$A$2:$A$158,'Data Set 2 - Vehicles'!$O$2:$O$158,"NF",0,-1), IF(OR('Data Set 1'!S23="Has No Vehicle",'Data Set 1'!S23="Has Only One Vehicle"),'Data Set 1'!S23,_xlpm.vserdate)) -> Has Only One Vehicle | V23: =SUMIF('Data Set 2 - Vehicles'!$A$2:$A$158,'Data Set 1'!A23,'Data Set 2 - Vehicles'!$Q$2:$Q$158) -> 233054 | W23: =_xlfn.LET(_xlpm.maxdate,_xlfn.MAXIFS('Data Set 2 - Vehicles'!$O$2:$O$158,'Data Set 2 - Vehicles'!$A$2:$A$158,'Data Set 1'!A23),IF(_xlpm.maxdate=0,"",_xlpm.maxdate)) -> 39636 | X23: =IF(W23="","No Service Record", IF(W23<EDATE(TODAY(),-48),"InActive","Active")) -> InActive | Y23: =IF(tblCustomers[[#This Row],[total mileage]]=0,"Customer has No Car", IF(AND(tblCustomers[[#This Row],[total mileage]]>0,tblCustomers[[#This Row],[total mileage]]<=100000),"50K - 100K", IF(AND(tblCustomers[[#This Row],[total mileage]]>100000,tblCustomers[[#This Row],[total mileage]]<=200000),"100K-200K","Mileage>200k"))) -> Mileage>200k
A24: 1244 | B24: My | C24: Rantanen | E24: 8 Mcarthur Ln | F24: Richboro | G24: PA | H24: 18954 | I24: =_xlfn.CONCAT(B24," ",C24) -> My Rantanen | J24: =IF(I24=" ",D24,I24) -> My Rantanen | K24: =_xlfn.TEXTBEFORE(E24, " ") -> 8 | L24: =VLOOKUP(A24,'Data Set 3 - Contacts'!$A$2:$F$136,5,FALSE) -> 2154915633 | M24: =VLOOKUP(A24,'Data Set 3 - Contacts'!$A$2:$F$136,6,FALSE) -> 2156472158 | N24: =VLOOKUP(A24,'Data Set 3 - Contacts'!$A$2:$F$136,4,FALSE) -> my@hotmail.com | O24: =_xlfn.XLOOKUP(A24,'Data Set 2 - Vehicles'!$A$2:$A$158,'Data Set 2 - Vehicles'!$B$2:$B$158,0,0,-1) -> 1 | P24: =_xlfn.XLOOKUP(A24,'Data Set 2 - Vehicles'!$A$2:$A$158,'Data Set 2 - Vehicles'!$E$2:$E$158,"Not Found",0,1) -> Civic | Q24: =IF(_xlfn.CONCAT(_xlfn.XLOOKUP(A24,'Data Set 2 - Vehicles'!$A$2:$A$158,'Data Set 2 - Vehicles'!$D$2:$D$158,"Not Found",0,1)," ",_xlfn.XLOOKUP(A24,'Data Set 2 - Vehicles'!$A$2:$A$158,'Data Set 2 - Vehicles'!$E$2:$E$158,"Not Found",0,1))="Not Found Not Found", "Not Found",_xlfn.CONCAT(_xlfn.XLOOKUP(A24,'Data Set 2 - Vehicles'!$A$2:$A$158,'Data Set 2 - Vehicles'!$D$2:$D$158,"Not Found",0,1)," ",_xlfn.XLOOKUP(A24,'Data Set 2 - Vehicles'!$A$2:$A$158,'Data Set 2 - Vehicles'!$E$2:$E$158,"Not Found",0,1))) -> Honda Civic | R24: =_xlfn.XLOOKUP(A24,'Data Set 2 - Vehicles'!$A$2:$A$158,'Data Set 2 - Vehicles'!$O$2:$O$158,"",0,1) -> 45586 | S24: =IF(_xlfn.XLOOKUP(A24,'Data Set 2 - Vehicles'!$A$2:$A$158,'Data Set 2 - Vehicles'!$E$2:$E$158,"Has No Vehicle",0,-1)=P24,"Has Only One Vehicle",_xlfn.XLOOKUP(A24,'Data Set 2 - Vehicles'!$A$2:$A$158,'Data Set 2 - Vehicles'!$E$2:$E$158,"Has No Vehcile",0,-1)) -> Has Only One Vehicle | T24: =_xlfn.LET(_xlpm.mfcname,_xlfn.XLOOKUP(A24,'Data Set 2 - Vehicles'!$A$2:$A$158,'Data Set 2 - Vehicles'!$D$2:$D$158,"NF",0,-1),_xlpm.mdlname,_xlfn.XLOOKUP(A24,'Data Set 2 - Vehicles'!$A$2:$A$158,'Data Set 2 - Vehicles'!$E$2:$E$158,"NF",0,-1),_xlpm.vehcilename,_xlfn.CONCAT(_xlpm.mfcname," ",_xlpm.mdlname),IF(S24="Has No Vehicle","Has No Vehicle",IF(S24="Has Only One Vehicle","Has Only One Vehicle",IF(_xlpm.vehcilename="NF NF","Not Found",_xlpm.vehcilename)))) -> Has Only One Vehicle | U24: =_xlfn.LET(_xlpm.vserdate,_xlfn.XLOOKUP(A24,'Data Set 2 - Vehicles'!$A$2:$A$158,'Data Set 2 - Vehicles'!$O$2:$O$158,"NF",0,-1), IF(OR('Data Set 1'!S24="Has No Vehicle",'Data Set 1'!S24="Has Only One Vehicle"),'Data Set 1'!S24,_xlpm.vserdate)) -> Has Only One Vehicle | V24: =SUMIF('Data Set 2 - Vehicles'!$A$2:$A$158,'Data Set 1'!A24,'Data Set 2 - Vehicles'!$Q$2:$Q$158) -> 290118 | W24: =_xlfn.LET(_xlpm.maxdate,_xlfn.MAXIFS('Data Set 2 - Vehicles'!$O$2:$O$158,'Data Set 2 - Vehicles'!$A$2:$A$158,'Data Set 1'!A24),IF(_xlpm.maxdate=0,"",_xlpm.maxdate)) -> 45586 | X24: =IF(W24="","No Service Record", IF(W24<EDATE(TODAY(),-48),"InActive","Active")) -> Active | Y24: =IF(tblCustomers[[#This Row],[total mileage]]=0,"Customer has No Car", IF(AND(tblCustomers[[#This Row],[total mileage]]>0,tblCustomers[[#This Row],[total mileage]]<=100000),"50K - 100K", IF(AND(tblCustomers[[#This Row],[total mileage]]>100000,tblCustomers[[#This Row],[total mileage]]<=200000),"100K-200K","Mileage>200k"))) -> Mileage>200k
A25: 1119 | B25: Scarlet | C25: Cartan | E25: 9390 S Howell Ave | F25: Albany | G25: GA | H25: 31701 | I25: =_xlfn.CONCAT(B25," ",C25) -> Scarlet Cartan | J25: =IF(I25=" ",D25,I25) -> Scarlet Cartan | K25: =_xlfn.TEXTBEFORE(E25, " ") -> 9390 | L25: =VLOOKUP(A25,'Data Set 3 - Contacts'!$A$2:$F$136,5,FALSE) -> 2297353378 | M25: =VLOOKUP(A25,'Data Set 3 - Contacts'!$A$2:$F$136,6,FALSE) | N25: =VLOOKUP(A25,'Data Set 3 - Contacts'!$A$2:$F$136,4,FALSE) -> scarlet.cartan@yahoo.com | O25: =_xlfn.XLOOKUP(A25,'Data Set 2 - Vehicles'!$A$2:$A$158,'Data Set 2 - Vehicles'!$B$2:$B$158,0,0,-1) -> 2 | P25: =_xlfn.XLOOKUP(A25,'Data Set 2 - Vehicles'!$A$2:$A$158,'Data Set 2 - Vehicles'!$E$2:$E$158,"Not Found",0,1) -> Carrera Cabrio | Q25: =IF(_xlfn.CONCAT(_xlfn.XLOOKUP(A25,'Data Set 2 - Vehicles'!$A$2:$A$158,'Data Set 2 - Vehicles'!$D$2:$D$158,"Not Found",0,1)," ",_xlfn.XLOOKUP(A25,'Data Set 2 - Vehicles'!$A$2:$A$158,'Data Set 2 - Vehicles'!$E$2:$E$158,"Not Found",0,1))="Not Found Not Found", "Not Found",_xlfn.CONCAT(_xlfn.XLOOKUP(A25,'Data Set 2 - Vehicles'!$A$2:$A$158,'Data Set 2 - Vehicles'!$D$2:$D$158,"Not Found",0,1)," ",_xlfn.XLOOKUP(A25,'Data Set 2 - Vehicles'!$A$2:$A$158,'Data Set 2 - Vehicles'!$E$2:$E$158,"Not Found",0,1))) -> Porsche Carrera Cabrio | R25: =_xlfn.XLOOKUP(A25,'Data Set 2 - Vehicles'!$A$2:$A$158,'Data Set 2 - Vehicles'!$O$2:$O$158,"",0,1) -> 43292 | S25: =IF(_xlfn.XLOOKUP(A25,'Data Set 2 - Vehicles'!$A$2:$A$158,'Data Set 2 - Vehicles'!$E$2:$E$158,"Has No Vehicle",0,-1)=P25,"Has Only One Vehicle",_xlfn.XLOOKUP(A25,'Data Set 2 - Vehicles'!$A$2:$A$158,'Data Set 2 - Vehicles'!$E$2:$E$158,"Has No Vehcile",0,-1)) -> Beetle | T25: =_xlfn.LET(_xlpm.mfcname,_xlfn.XLOOKUP(A25,'Data Set 2 - Vehicles'!$A$2:$A$158,'Data Set 2 - Vehicles'!$D$2:$D$158,"NF",0,-1),_xlpm.mdlname,_xlfn.XLOOKUP(A25,'Data Set 2 - Vehicles'!$A$2:$A$158,'Data Set 2 - Vehicles'!$E$2:$E$158,"NF",0,-1),_xlpm.vehcilename,_xlfn.CONCAT(_xlpm.mfcname," ",_xlpm.mdlname),IF(S25="Has No Vehicle","Has No Vehicle",IF(S25="Has Only One Vehicle","Has Only One Vehicle",IF(_xlpm.vehcilename="NF NF","Not Found",_xlpm.vehcilename)))) -> Volkswagen Beetle | U25: =_xlfn.LET(_xlpm.vserdate,_xlfn.XLOOKUP(A25,'Data Set 2 - Vehicles'!$A$2:$A$158,'Data Set 2 - Vehicles'!$O$2:$O$158,"NF",0,-1), IF(OR('Data Set 1'!S25="Has No Vehicle",'Data Set 1'!S25="Has Only One Vehicle"),'Data Set 1'!S25,_xlpm.vserdate)) -> 44489 | V25: =SUMIF('Data Set 2 - Vehicles'!$A$2:$A$158,'Data Set 1'!A25,'Data Set 2 - Vehicles'!$Q$2:$Q$158) -> 422795 | W25: =_xlfn.LET(_xlpm.maxdate,_xlfn.MAXIFS('Data Set 2 - Vehicles'!$O$2:$O$158,'Data Set 2 - Vehicles'!$A$2:$A$158,'Data Set 1'!A25),IF(_xlpm.maxdate=0,"",_xlpm.maxdate)) -> 44489 | X25: =IF(W25="","No Service Record", IF(W25<EDATE(TODAY(),-48),"InActive","Active")) -> InActive | Y25: =IF(tblCustomers[[#This Row],[total mileage]]=0,"Customer has No Car", IF(AND(tblCustomers[[#This Row],[total mileage]]>0,tblCustomers[[#This Row],[total mileage]]<=100000),"50K - 100K", IF(AND(tblCustomers[[#This Row],[total mileage]]>100000,tblCustomers[[#This Row],[total mileage]]<=200000),"100K-200K","Mileage>200k"))) -> Mileage>200k
A26: 1285 | D26: Bradley Nameplate Corp | E26: 87 Imperial Ct #79 | F26: Fargo | G26: ND | H26: 58102 | I26: =_xlfn.CONCAT(B26," ",C26) | J26: =IF(I26=" ",D26,I26) -> Bradley Nameplate Corp | K26: =_xlfn.TEXTBEFORE(E26, " ") -> 87 | L26: =VLOOKUP(A26,'Data Set 3 - Contacts'!$A$2:$F$136,5,FALSE) -> 7018982154 | M26: =VLOOKUP(A26,'Data Set 3 - Contacts'!$A$2:$F$136,6,FALSE) -> 7014217080 | N26: =VLOOKUP(A26,'Data Set 3 - Contacts'!$A$2:$F$136,4,FALSE) -> lavonda@cox.net | O26: =_xlfn.XLOOKUP(A26,'Data Set 2 - Vehicles'!$A$2:$A$158,'Data Set 2 - Vehicles'!$B$2:$B$158,0,0,-1) -> 1 | P26: =_xlfn.XLOOKUP(A26,'Data Set 2 - Vehicles'!$A$2:$A$158,'Data Set 2 - Vehicles'!$E$2:$E$158,"Not Found",0,1) -> S-Type | Q26: =IF(_xlfn.CONCAT(_xlfn.XLOOKUP(A26,'Data Set 2 - Vehicles'!$A$2:$A$158,'Data Set 2 - Vehicles'!$D$2:$D$158,"Not Found",0,1)," ",_xlfn.XLOOKUP(A26,'Data Set 2 - Vehicles'!$A$2:$A$158,'Data Set 2 - Vehicles'!$E$2:$E$158,"Not Found",0,1))="Not Found Not Found", "Not Found",_xlfn.CONCAT(_xlfn.XLOOKUP(A26,'Data Set 2 - Vehicles'!$A$2:$A$158,'Data Set 2 - Vehicles'!$D$2:$D$158,"Not Found",0,1)," ",_xlfn.XLOOKUP(A26,'Data Set 2 - Vehicles'!$A$2:$A$158,'Data Set 2 - Vehicles'!$E$2:$E$158,"Not Found",0,1))) -> Jaguar S-Type | R26: =_xlfn.XLOOKUP(A26,'Data Set 2 - Vehicles'!$A$2:$A$158,'Data Set 2 - Vehicles'!$O$2:$O$158,"",0,1) -> 44868 | S26: =IF(_xlfn.XLOOKUP(A26,'Data Set 2 - Vehicles'!$A$2:$A$158,'Data Set 2 - Vehicles'!$E$2:$E$158,"Has No Vehicle",0,-1)=P26,"Has Only One Vehicle",_xlfn.XLOOKUP(A26,'Data Set 2 - Vehicles'!$A$2:$A$158,'Data Set 2 - Vehicles'!$E$2:$E$158,"Has No Vehcile",0,-1)) -> Has Only One Vehicle | T26: =_xlfn.LET(_xlpm.mfcname,_xlfn.XLOOKUP(A26,'Data Set 2 - Vehicles'!$A$2:$A$158,'Data Set 2 - Vehicles'!$D$2:$D$158,"NF",0,-1),_xlpm.mdlname,_xlfn.XLOOKUP(A26,'Data Set 2 - Vehicles'!$A$2:$A$158,'Data Set 2 - Vehicles'!$E$2:$E$158,"NF",0,-1),_xlpm.vehcilename,_xlfn.CONCAT(_xlpm.mfcname," ",_xlpm.mdlname),IF(S26="Has No Vehicle","Has No Vehicle",IF(S26="Has Only One Vehicle","Has Only One Vehicle",IF(_xlpm.vehcilename="NF NF","Not Found",_xlpm.vehcilename)))) -> Has Only One Vehicle | U26: =_xlfn.LET(_xlpm.vserdate,_xlfn.XLOOKUP(A26,'Data Set 2 - Vehicles'!$A$2:$A$158,'Data Set 2 - Vehicles'!$O$2:$O$158,"NF",0,-1), IF(OR('Data Set 1'!S26="Has No Vehicle",'Data Set 1'!S26="Has Only One Vehicle"),'Data Set 1'!S26,_xlpm.vserdate)) -> Has Only One Vehicle | V26: =SUMIF('Data Set 2 - Vehicles'!$A$2:$A$158,'Data Set 1'!A26,'Data Set 2 - Vehicles'!$Q$2:$Q$158) -> 234341 | W26: =_xlfn.LET(_xlpm.maxdate,_xlfn.MAXIFS('Data Set 2 - Vehicles'!$O$2:$O$158,'Data Set 2 - Vehicles'!$A$2:$A$158,'Data Set 1'!A26),IF(_xlpm.maxdate=0,"",_xlpm.maxdate)) -> 44868 | X26: =IF(W26="","No Service Record", IF(W26<EDATE(TODAY(),-48),"InActive","Active")) -> Active | Y26: =IF(tblCustomers[[#This Row],[total mileage]]=0,"Customer has No Car", IF(AND(tblCustomers[[#This Row],[total mileage]]>0,tblCustomers[[#This Row],[total mileage]]<=100000),"50K - 100K", IF(AND(tblCustomers[[#This Row],[total mileage]]>100000,tblCustomers[[#This Row],[total mileage]]<=200000),"100K-200K","Mileage>200k"))) -> Mileage>200k
A27: 1121 | D27: Bresler Eitel Framg Gllry Ltd | E27: 4646 Kaahumanu St | F27: Hackensack | G27: NJ | H27: 7601 | I27: =_xlfn.CONCAT(B27," ",C27) | J27: =IF(I27=" ",D27,I27) -> Bresler Eitel Framg Gllry Ltd | K27: =_xlfn.TEXTBEFORE(E27, " ") -> 4646 | L27: =VLOOKUP(A27,'Data Set 3 - Contacts'!$A$2:$F$136,5,FALSE) -> 2016721553 | M27: =VLOOKUP(A27,'Data Set 3 - Contacts'!$A$2:$F$136,6,FALSE) | N27: =VLOOKUP(A27,'Data Set 3 - Contacts'!$A$2:$F$136,4,FALSE) -> tsmith@aol.com | O27: =_xlfn.XLOOKUP(A27,'Data Set 2 - Vehicles'!$A$2:$A$158,'Data Set 2 - Vehicles'!$B$2:$B$158,0,0,-1) -> 1 | P27: =_xlfn.XLOOKUP(A27,'Data Set 2 - Vehicles'!$A$2:$A$158,'Data Set 2 - Vehicles'!$E$2:$E$158,"Not Found",0,1) -> Ram Pickup | Q27: =IF(_xlfn.CONCAT(_xlfn.XLOOKUP(A27,'Data Set 2 - Vehicles'!$A$2:$A$158,'Data Set 2 - Vehicles'!$D$2:$D$158,"Not Found",0,1)," ",_xlfn.XLOOKUP(A27,'Data Set 2 - Vehicles'!$A$2:$A$158,'Data Set 2 - Vehicles'!$E$2:$E$158,"Not Found",0,1))="Not Found Not Found", "Not Found",_xlfn.CONCAT(_xlfn.XLOOKUP(A27,'Data Set 2 - Vehicles'!$A$2:$A$158,'Data Set 2 - Vehicles'!$D$2:$D$158,"Not Found",0,1)," ",_xlfn.XLOOKUP(A27,'Data Set 2 - Vehicles'!$A$2:$A$158,'Data Set 2 - Vehicles'!$E$2:$E$158,"Not Found",0,1))) -> Dodge Ram Pickup | R27: =_xlfn.XLOOKUP(A27,'Data Set 2 - Vehicles'!$A$2:$A$158,'Data Set 2 - Vehicles'!$O$2:$O$158,"",0,1) -> 45357 | S27: =IF(_xlfn.XLOOKUP(A27,'Data Set 2 - Vehicles'!$A$2:$A$158,'Data Set 2 - Vehicles'!$E$2:$E$158,"Has No Vehicle",0,-1)=P27,"Has Only One Vehicle",_xlfn.XLOOKUP(A27,'Data Set 2 - Vehicles'!$A$2:$A$158,'Data Set 2 - Vehicles'!$E$2:$E$158,"Has No Vehcile",0,-1)) -> Has Only One Vehicle | T27: =_xlfn.LET(_xlpm.mfcname,_xlfn.XLOOKUP(A27,'Data Set 2 - Vehicles'!$A$2:$A$158,'Data Set 2 - Vehicles'!$D$2:$D$158,"NF",0,-1),_xlpm.mdlname,_xlfn.XLOOKUP(A27,'Data Set 2 - Vehicles'!$A$2:$A$158,'Data Set 2 - Vehicles'!$E$2:$E$158,"NF",0,-1),_xlpm.vehcilename,_xlfn.CONCAT(_xlpm.mfcname," ",_xlpm.mdlname),IF(S27="Has No Vehicle","Has No Vehicle",IF(S27="Has Only One Vehicle","Has Only One Vehicle",IF(_xlpm.vehcilename="NF NF","Not Found",_xlpm.vehcilename)))) -> Has Only One Vehicle | U27: =_xlfn.LET(_xlpm.vserdate,_xlfn.XLOOKUP(A27,'Data Set 2 - Vehicles'!$A$2:$A$158,'Data Set 2 - Vehicles'!$O$2:$O$158,"NF",0,-1), IF(OR('Data Set 1'!S27="Has No Vehicle",'Data Set 1'!S27="Has Only One Vehicle"),'Data Set 1'!S27,_xlpm.vserdate)) -> Has Only One Vehicle | V27: =SUMIF('Data Set 2 - Vehicles'!$A$2:$A$158,'Data Set 1'!A27,'Data Set 2 - Vehicles'!$Q$2:$Q$158) -> 260003 | W27: =_xlfn.LET(_xlpm.maxdate,_xlfn.MAXIFS('Data Set 2 - Vehicles'!$O$2:$O$158,'Data Set 2 - Vehicles'!$A$2:$A$158,'Data Set 1'!A27),IF(_xlpm.maxdate=0,"",_xlpm.maxdate)) -> 45357 | X27: =IF(W27="","No Service Record", IF(W27<EDATE(TODAY(),-48),"InActive","Active")) -> Active | Y27: =IF(tblCustomers[[#This Row],[total mileage]]=0,"Customer has No Car", IF(AND(tblCustomers[[#This Row],[total mileage]]>0,tblCustomers[[#This Row],[total mileage]]<=100000),"50K - 100K", IF(AND(tblCustomers[[#This Row],[total mileage]]>100000,tblCustomers[[#This Row],[total mileage]]<=200000),"100K-200K","Mileage>200k"))) -> Mileage>200k
A28: 1411 | B28: Mitzie | C28: Hudnall | D28: Cangro Transmission Co | E28: 17 Jersey Ave | F28: Englewood | G28: CO | H28: 80110 | I28: =_xlfn.CONCAT(B28," ",C28) -> Mitzie Hudnall | J28: =IF(I28=" ",D28,I28) -> Mitzie Hudnall | K28: =_xlfn.TEXTBEFORE(E28, " ") -> 17 | L28: =VLOOKUP(A28,'Data Set 3 - Contacts'!$A$2:$F$136,5,FALSE) -> 3034021940 | M28: =VLOOKUP(A28,'Data Set 3 - Contacts'!$A$2:$F$136,6,FALSE) -> 3039977760 | N28: =VLOOKUP(A28,'Data Set 3 - Contacts'!$A$2:$F$136,4,FALSE) -> mitzie_hudnall@yahoo.com | O28: =_xlfn.XLOOKUP(A28,'Data Set 2 - Vehicles'!$A$2:$A$158,'Data Set 2 - Vehicles'!$B$2:$B$158,0,0,-1) -> 1 | P28: =_xlfn.XLOOKUP(A28,'Data Set 2 - Vehicles'!$A$2:$A$158,'Data Set 2 - Vehicles'!$E$2:$E$158,"Not Found",0,1) -> Malibu | Q28: =IF(_xlfn.CONCAT(_xlfn.XLOOKUP(A28,'Data Set 2 - Vehicles'!$A$2:$A$158,'Data Set 2 - Vehicles'!$D$2:$D$158,"Not Found",0,1)," ",_xlfn.XLOOKUP(A28,'Data Set 2 - Vehicles'!$A$2:$A$158,'Data Set 2 - Vehicles'!$E$2:$E$158,"Not Found",0,1))="Not Found Not Found", "Not Found",_xlfn.CONCAT(_xlfn.XLOOKUP(A28,'Data Set 2 - Vehicles'!$A$2:$A$158,'Data Set 2 - Vehicles'!$D$2:$D$158,"Not Found",0,1)," ",_xlfn.XLOOKUP(A28,'Data Set 2 - Vehicles'!$A$2:$A$158,'Data Set 2 - Vehicles'!$E$2:$E$158,"Not Found",0,1))) -> Chevrolet Malibu | R28: =_xlfn.XLOOKUP(A28,'Data Set 2 - Vehicles'!$A$2:$A$158,'Data Set 2 - Vehicles'!$O$2:$O$158,"",0,1) -> 44639 | S28: =IF(_xlfn.XLOOKUP(A28,'Data Set 2 - Vehicles'!$A$2:$A$158,'Data Set 2 - Vehicles'!$E$2:$E$158,"Has No Vehicle",0,-1)=P28,"Has Only One Vehicle",_xlfn.XLOOKUP(A28,'Data Set 2 - Vehicles'!$A$2:$A$158,'Data Set 2 - Vehicles'!$E$2:$E$158,"Has No Vehcile",0,-1)) -> Has Only One Vehicle | T28: =_xlfn.LET(_xlpm.mfcname,_xlfn.XLOOKUP(A28,'Data Set 2 - Vehicles'!$A$2:$A$158,'Data Set 2 - Vehicles'!$D$2:$D$158,"NF",0,-1),_xlpm.mdlname,_xlfn.XLOOKUP(A28,'Data Set 2 - Vehicles'!$A$2:$A$158,'Data Set 2 - Vehicles'!$E$2:$E$158,"NF",0,-1),_xlpm.vehcilename,_xlfn.CONCAT(_xlpm.mfcname," ",_xlpm.mdlname),IF(S28="Has No Vehicle","Has No Vehicle",IF(S28="Has Only One Vehicle","Has Only One Vehicle",IF(_xlpm.vehcilename="NF NF","Not Found",_xlpm.vehcilename)))) -> Has Only One Vehicle | U28: =_xlfn.LET(_xlpm.vserdate,_xlfn.XLOOKUP(A28,'Data Set 2 - Vehicles'!$A$2:$A$158,'Data Set 2 - Vehicles'!$O$2:$O$158,"NF",0,-1), IF(OR('Data Set 1'!S28="Has No Vehicle",'Data Set 1'!S28="Has Only One Vehicle"),'Data Set 1'!S28,_xlpm.vserdate)) -> Has Only One Vehicle | V28: =SUMIF('Data Set 2 - Vehicles'!$A$2:$A$158,'Data Set 1'!A28,'Data Set 2 - Vehicles'!$Q$2:$Q$158) -> 148159 | W28: =_xlfn.LET(_xlpm.maxdate,_xlfn.MAXIFS('Data Set 2 - Vehicles'!$O$2:$O$158,'Data Set 2 - Vehicles'!$A$2:$A$158,'Data Set 1'!A28),IF(_xlpm.maxdate=0,"",_xlpm.maxdate)) -> 44639 | X28: =IF(W28="","No Service Record", IF(W28<EDATE(TODAY(),-48),"InActive","Active")) -> InActive | Y28: =IF(tblCustomers[[#This Row],[total mileage]]=0,"Customer has No Car", IF(AND(tblCustomers[[#This Row],[total mileage]]>0,tblCustomers[[#This Row],[total mileage]]<=100000),"50K - 100K", IF(AND(tblCustomers[[#This Row],[total mileage]]>100000,tblCustomers[[#This Row],[total mileage]]<=200000),"100K-200K","Mileage>200k"))) -> 100K-200K
A29: 1466 | D29: Carriage House Cllsn Rpr Inc | E29: 35 E Main St #43 | F29: Elk Grove Village | G29: IL | H29: 60007 | I29: =_xlfn.CONCAT(B29," ",C29) | J29: =IF(I29=" ",D29,I29) -> Carriage House Cllsn Rpr Inc | K29: =_xlfn.TEXTBEFORE(E29, " ") -> 35 | L29: =VLOOKUP(A29,'Data Set 3 - Contacts'!$A$2:$F$136,5,FALSE) -> 8475195906 | M29: =VLOOKUP(A29,'Data Set 3 - Contacts'!$A$2:$F$136,6,FALSE) -> 8477405304 | N29: =VLOOKUP(A29,'Data Set 3 - Contacts'!$A$2:$F$136,4,FALSE) -> joni_breland@cox.net | O29: =_xlfn.XLOOKUP(A29,'Data Set 2 - Vehicles'!$A$2:$A$158,'Data Set 2 - Vehicles'!$B$2:$B$158,0,0,-1) -> 1 | P29: =_xlfn.XLOOKUP(A29,'Data Set 2 - Vehicles'!$A$2:$A$158,'Data Set 2 - Vehicles'!$E$2:$E$158,"Not Found",0,1) -> 3000GT | Q29: =IF(_xlfn.CONCAT(_xlfn.XLOOKUP(A29,'Data Set 2 - Vehicles'!$A$2:$A$158,'Data Set 2 - Vehicles'!$D$2:$D$158,"Not Found",0,1)," ",_xlfn.XLOOKUP(A29,'Data Set 2 - Vehicles'!$A$2:$A$158,'Data Set 2 - Vehicles'!$E$2:$E$158,"Not Found",0,1))="Not Found Not Found", "Not Found",_xlfn.CONCAT(_xlfn.XLOOKUP(A29,'Data Set 2 - Vehicles'!$A$2:$A$158,'Data Set 2 - Vehicles'!$D$2:$D$158,"Not Found",0,1)," ",_xlfn.XLOOKUP(A29,'Data Set 2 - Vehicles'!$A$2:$A$158,'Data Set 2 - Vehicles'!$E$2:$E$158,"Not Found",0,1))) -> Mitsubishi 3000GT | R29: =_xlfn.XLOOKUP(A29,'Data Set 2 - Vehicles'!$A$2:$A$158,'Data Set 2 - Vehicles'!$O$2:$O$158,"",0,1) -> 42915 | S29: =IF(_xlfn.XLOOKUP(A29,'Data Set 2 - Vehicles'!$A$2:$A$158,'Data Set 2 - Vehicles'!$E$2:$E$158,"Has No Vehicle",0,-1)=P29,"Has Only One Vehicle",_xlfn.XLOOKUP(A29,'Data Set 2 - Vehicles'!$A$2:$A$158,'Data Set 2 - Vehicles'!$E$2:$E$158,"Has No Vehcile",0,-1)) -> Has Only One Vehicle | T29: =_xlfn.LET(_xlpm.mfcname,_xlfn.XLOOKUP(A29,'Data Set 2 - Vehicles'!$A$2:$A$158,'Data Set 2 - Vehicles'!$D$2:$D$158,"NF",0,-1),_xlpm.mdlname,_xlfn.XLOOKUP(A29,'Data Set 2 - Vehicles'!$A$2:$A$158,'Data Set 2 - Vehicles'!$E$2:$E$158,"NF",0,-1),_xlpm.vehcilename,_xlfn.CONCAT(_xlpm.mfcname," ",_xlpm.mdlname),IF(S29="Has No Vehicle","Has No Vehicle",IF(S29="Has Only One Vehicle","Has Only One Vehicle",IF(_xlpm.vehcilename="NF NF","Not Found",_xlpm.vehcilename)))) -> Has Only One Vehicle | U29: =_xlfn.LET(_xlpm.vserdate,_xlfn.XLOOKUP(A29,'Data Set 2 - Vehicles'!$A$2:$A$158,'Data Set 2 - Vehicles'!$O$2:$O$158,"NF",0,-1), IF(OR('Data Set 1'!S29="Has No Vehicle",'Data Set 1'!S29="Has Only One Vehicle"),'Data Set 1'!S29,_xlpm.vserdate)) -> Has Only One Vehicle | V29: =SUMIF('Data Set 2 - Vehicles'!$A$2:$A$158,'Data Set 1'!A29,'Data Set 2 - Vehicles'!$Q$2:$Q$158) -> 146859 | W29: =_xlfn.LET(_xlpm.maxdate,_xlfn.MAXIFS('Data Set 2 - Vehicles'!$O$2:$O$158,'Data Set 2 - Vehicles'!$A$2:$A$158,'Data Set 1'!A29),IF(_xlpm.maxdate=0,"",_xlpm.maxdate)) -> 42915 | X29: =IF(W29="","No Service Record", IF(W29<EDATE(TODAY(),-48),"InActive","Active")) -> InActive | Y29: =IF(tblCustomers[[#This Row],[total mileage]]=0,"Customer has No Car", IF(AND(tblCustomers[[#This Row],[total mileage]]>0,tblCustomers[[#This Row],[total mileage]]<=100000),"50K - 100K", IF(AND(tblCustomers[[#This Row],[total mileage]]>100000,tblCustomers[[#This Row],[total mileage]]<=200000),"100K-200K","Mileage>200k"))) -> 100K-200K
A30: 1113 | B30: Jesusa | C30: Shin | E30: 2239 Shawnee Mission Pky | F30: Tullahoma | G30: TN | H30: 37388 | I30: =_xlfn.CONCAT(B30," ",C30) -> Jesusa Shin | J30: =IF(I30=" ",D30,I30) -> Jesusa Shin | K30: =_xlfn.TEXTBEFORE(E30, " ") -> 2239 | L30: =VLOOKUP(A30,'Data Set 3 - Contacts'!$A$2:$F$136,5,FALSE) -> 9312738709 | M30: =VLOOKUP(A30,'Data Set 3 - Contacts'!$A$2:$F$136,6,FALSE) -> 9317391551 | N30: =VLOOKUP(A30,'Data Set 3 - Contacts'!$A$2:$F$136,4,FALSE) -> jshin@shin.com | O30: =_xlfn.XLOOKUP(A30,'Data Set 2 - Vehicles'!$A$2:$A$158,'Data Set 2 - Vehicles'!$B$2:$B$158,0,0,-1) -> 1 | P30: =_xlfn.XLOOKUP(A30,'Data Set 2 - Vehicles'!$A$2:$A$158,'Data Set 2 - Vehicles'!$E$2:$E$158,"Not Found",0,1) -> GS400 | Q30: =IF(_xlfn.CONCAT(_xlfn.XLOOKUP(A30,'Data Set 2 - Vehicles'!$A$2:$A$158,'Data Set 2 - Vehicles'!$D$2:$D$158,"Not Found",0,1)," ",_xlfn.XLOOKUP(A30,'Data Set 2 - Vehicles'!$A$2:$A$158,'Data Set 2 - Vehicles'!$E$2:$E$158,"Not Found",0,1))="Not Found Not Found", "Not Found",_xlfn.CONCAT(_xlfn.XLOOKUP(A30,'Data Set 2 - Vehicles'!$A$2:$A$158,'Data Set 2 - Vehicles'!$D$2:$D$158,"Not Found",0,1)," ",_xlfn.XLOOKUP(A30,'Data Set 2 - Vehicles'!$A$2:$A$158,'Data Set 2 - Vehicles'!$E$2:$E$158,"Not Found",0,1))) -> Lexus GS400 | R30: =_xlfn.XLOOKUP(A30,'Data Set 2 - Vehicles'!$A$2:$A$158,'Data Set 2 - Vehicles'!$O$2:$O$158,"",0,1) -> 40145 | S30: =IF(_xlfn.XLOOKUP(A30,'Data Set 2 - Vehicles'!$A$2:$A$158,'Data Set 2 - Vehicles'!$E$2:$E$158,"Has No Vehicle",0,-1)=P30,"Has Only One Vehicle",_xlfn.XLOOKUP(A30,'Data Set 2 - Vehicles'!$A$2:$A$158,'Data Set 2 - Vehicles'!$E$2:$E$158,"Has No Vehcile",0,-1)) -> Has Only One Vehicle | T30: =_xlfn.LET(_xlpm.mfcname,_xlfn.XLOOKUP(A30,'Data Set 2 - Vehicles'!$A$2:$A$158,'Data Set 2 - Vehicles'!$D$2:$D$158,"NF",0,-1),_xlpm.mdlname,_xlfn.XLOOKUP(A30,'Data Set 2 - Vehicles'!$A$2:$A$158,'Data Set 2 - Vehicles'!$E$2:$E$158,"NF",0,-1),_xlpm.vehcilename,_xlfn.CONCAT(_xlpm.mfcname," ",_xlpm.mdlname),IF(S30="Has No Vehicle","Has No Vehicle",IF(S30="Has Only One Vehicle","Has Only One Vehicle",IF(_xlpm.vehcilename="NF NF","Not Found",_xlpm.vehcilename)))) -> Has Only One Vehicle | U30: =_xlfn.LET(_xlpm.vserdate,_xlfn.XLOOKUP(A30,'Data Set 2 - Vehicles'!$A$2:$A$158,'Data Set 2 - Vehicles'!$O$2:$O$158,"NF",0,-1), IF(OR('Data Set 1'!S30="Has No Vehicle",'Data Set 1'!S30="Has Only One Vehicle"),'Data Set 1'!S30,_xlpm.vserdate)) -> Has Only One Vehicle | V30: =SUMIF('Data Set 2 - Vehicles'!$A$2:$A$158,'Data Set 1'!A30,'Data Set 2 - Vehicles'!$Q$2:$Q$158) -> 294792 | W30: =_xlfn.LET(_xlpm.maxdate,_xlfn.MAXIFS('Data Set 2 - Vehicles'!$O$2:$O$158,'Data Set 2 - Vehicles'!$A$2:$A$158,'Data Set 1'!A30),IF(_xlpm.maxdate=0,"",_xlpm.maxdate)) -> 40145 | X30: =IF(W30="","No Service Record", IF(W30<EDATE(TODAY(),-48),"InActive","Active")) -> InActive | Y30: =IF(tblCustomers[[#This Row],[total mileage]]=0,"Customer has No Car", IF(AND(tblCustomers[[#This Row],[total mileage]]>0,tblCustomers[[#This Row],[total mileage]]<=100000),"50K - 100K", IF(AND(tblCustomers[[#This Row],[total mileage]]>100000,tblCustomers[[#This Row],[total mileage]]<=200000),"100K-200K","Mileage>200k"))) -> Mileage>200k
A31: 1032 | D31: Cascade Realty Advisors Inc | E31: 366 South Dr | F31: Las Cruces | G31: NM | H31: 88011 | I31: =_xlfn.CONCAT(B31," ",C31) | J31: =IF(I31=" ",D31,I31) -> Cascade Realty Advisors Inc | K31: =_xlfn.TEXTBEFORE(E31, " ") -> 366 | L31: =VLOOKUP(A31,'Data Set 3 - Contacts'!$A$2:$F$136,5,FALSE) -> 5059773911 | M31: =VLOOKUP(A31,'Data Set 3 - Contacts'!$A$2:$F$136,6,FALSE) | N31: =VLOOKUP(A31,'Data Set 3 - Contacts'!$A$2:$F$136,4,FALSE) -> francine_vocelka@vocelka.com | O31: =_xlfn.XLOOKUP(A31,'Data Set 2 - Vehicles'!$A$2:$A$158,'Data Set 2 - Vehicles'!$B$2:$B$158,0,0,-1) -> 2 | P31: =_xlfn.XLOOKUP(A31,'Data Set 2 - Vehicles'!$A$2:$A$158,'Data Set 2 - Vehicles'!$E$2:$E$158,"Not Found",0,1) -> GTI | Q31: =IF(_xlfn.CONCAT(_xlfn.XLOOKUP(A31,'Data Set 2 - Vehicles'!$A$2:$A$158,'Data Set 2 - Vehicles'!$D$2:$D$158,"Not Found",0,1)," ",_xlfn.XLOOKUP(A31,'Data Set 2 - Vehicles'!$A$2:$A$158,'Data Set 2 - Vehicles'!$E$2:$E$158,"Not Found",0,1))="Not Found Not Found", "Not Found",_xlfn.CONCAT(_xlfn.XLOOKUP(A31,'Data Set 2 - Vehicles'!$A$2:$A$158,'Data Set 2 - Vehicles'!$D$2:$D$158,"Not Found",0,1)," ",_xlfn.XLOOKUP(A31,'Data Set 2 - Vehicles'!$A$2:$A$158,'Data Set 2 - Vehicles'!$E$2:$E$158,"Not Found",0,1))) -> Volkswagen GTI | R31: =_xlfn.XLOOKUP(A31,'Data Set 2 - Vehicles'!$A$2:$A$158,'Data Set 2 - Vehicles'!$O$2:$O$158,"",0,1) -> 40269 | S31: =IF(_xlfn.XLOOKUP(A31,'Data Set 2 - Vehicles'!$A$2:$A$158,'Data Set 2 - Vehicles'!$E$2:$E$158,"Has No Vehicle",0,-1)=P31,"Has Only One Vehicle",_xlfn.XLOOKUP(A31,'Data Set 2 - Vehicles'!$A$2:$A$158,'Data Set 2 - Vehicles'!$E$2:$E$158,"Has No Vehcile",0,-1)) -> Carrera Coupe | T31: =_xlfn.LET(_xlpm.mfcname,_xlfn.XLOOKUP(A31,'Data Set 2 - Vehicles'!$A$2:$A$158,'Data Set 2 - Vehicles'!$D$2:$D$158,"NF",0,-1),_xlpm.mdlname,_xlfn.XLOOKUP(A31,'Data Set 2 - Vehicles'!$A$2:$A$158,'Data Set 2 - Vehicles'!$E$2:$E$158,"NF",0,-1),_xlpm.vehcilename,_xlfn.CONCAT(_xlpm.mfcname," ",_xlpm.mdlname),IF(S31="Has No Vehicle","Has No Vehicle",IF(S31="Has Only One Vehicle","Has Only One Vehicle",IF(_xlpm.vehcilename="NF NF","Not Found",_xlpm.vehcilename)))) -> Porsche Carrera Coupe | U31: =_xlfn.LET(_xlpm.vserdate,_xlfn.XLOOKUP(A31,'Data Set 2 - Vehicles'!$A$2:$A$158,'Data Set 2 - Vehicles'!$O$2:$O$158,"NF",0,-1), IF(OR('Data Set 1'!S31="Has No Vehicle",'Data Set 1'!S31="Has Only One Vehicle"),'Data Set 1'!S31,_xlpm.vserdate)) -> 40533 | V31: =SUMIF('Data Set 2 - Vehicles'!$A$2:$A$158,'Data Set 1'!A31,'Data Set 2 - Vehicles'!$Q$2:$Q$158) -> 239482 | W31: =_xlfn.LET(_xlpm.maxdate,_xlfn.MAXIFS('Data Set 2 - Vehicles'!$O$2:$O$158,'Data Set 2 - Vehicles'!$A$2:$A$158,'Data Set 1'!A31),IF(_xlpm.maxdate=0,"",_xlpm.maxdate)) -> 40533 | X31: =IF(W31="","No Service Record", IF(W31<EDATE(TODAY(),-48),"InActive","Active")) -> InActive | Y31: =IF(tblCustomers[[#This Row],[total mileage]]=0,"Customer has No Car", IF(AND(tblCustomers[[#This Row],[total mileage]]>0,tblCustomers[[#This Row],[total mileage]]<=100000),"50K - 100K", IF(AND(tblCustomers[[#This Row],[total mileage]]>100000,tblCustomers[[#This Row],[total mileage]]<=200000),"100K-200K","Mileage>200k"))) -> Mileage>200k
